{
  "timestamp": "2025-10-02T13:50:08.271502",
  "total_tests": 7,
  "passed": 0,
  "failed": 7,
  "results": [
    {
      "test_id": "TEST_01_PERFECT_CLAIM",
      "description": "Perfect legitimate claim - should APPROVE",
      "passed": false,
      "error": "python: can't open file 'C:\\\\Users\\\\gupta\\\\OneDrive\\\\Documents\\\\project\\\\PBI\\\\cropfarmPY\\\\devil_ai.py': [Errno 2] No such file or directory\n",
      "expected": "APPROVE",
      "actual": "ERROR"
    },
    {
      "test_id": "TEST_02_HIGH_FRAUD_RISK",
      "description": "High fraud risk - GPS outside boundary, high claim history",
      "passed": false,
      "error": "python: can't open file 'C:\\\\Users\\\\gupta\\\\OneDrive\\\\Documents\\\\project\\\\PBI\\\\cropfarmPY\\\\devil_ai.py': [Errno 2] No such file or directory\n",
      "expected": "REJECT",
      "actual": "ERROR"
    },
    {
      "test_id": "TEST_03_MEDIUM_CONFIDENCE",
      "description": "Medium confidence - requires manual review",
      "passed": false,
      "error": "python: can't open file 'C:\\\\Users\\\\gupta\\\\OneDrive\\\\Documents\\\\project\\\\PBI\\\\cropfarmPY\\\\devil_ai.py': [Errno 2] No such file or directory\n",
      "expected": "MANUAL_REVIEW",
      "actual": "ERROR"
    },
    {
      "test_id": "TEST_04_EXAGGERATED_CLAIM",
      "description": "Farmer claiming much more damage than calculated",
      "passed": false,
      "error": "python: can't open file 'C:\\\\Users\\\\gupta\\\\OneDrive\\\\Documents\\\\project\\\\PBI\\\\cropfarmPY\\\\devil_ai.py': [Errno 2] No such file or directory\n",
      "expected": "MANUAL_REVIEW",
      "actual": "ERROR"
    },
    {
      "test_id": "TEST_05_LOW_DAMAGE_CLAIM",
      "description": "Low damage claim - minimal damage detected",
      "passed": false,
      "error": "python: can't open file 'C:\\\\Users\\\\gupta\\\\OneDrive\\\\Documents\\\\project\\\\PBI\\\\cropfarmPY\\\\devil_ai.py': [Errno 2] No such file or directory\n",
      "expected": "APPROVE",
      "actual": "ERROR"
    },
    {
      "test_id": "TEST_06_REPEAT_OFFENDER",
      "description": "Farmer with multiple previous claims",
      "passed": false,
      "error": "python: can't open file 'C:\\\\Users\\\\gupta\\\\OneDrive\\\\Documents\\\\project\\\\PBI\\\\cropfarmPY\\\\devil_ai.py': [Errno 2] No such file or directory\n",
      "expected": "MANUAL_REVIEW",
      "actual": "ERROR"
    },
    {
      "test_id": "TEST_07_EDGE_CASE_BOUNDARY",
      "description": "GPS coordinates at edge of farm boundary",
      "passed": false,
      "error": "python: can't open file 'C:\\\\Users\\\\gupta\\\\OneDrive\\\\Documents\\\\project\\\\PBI\\\\cropfarmPY\\\\devil_ai.py': [Errno 2] No such file or directory\n",
      "expected": "APPROVE",
      "actual": "ERROR"
    }
  ]
}